<?xml version="1.0"?>
<robot xmlns:xacro="http://www.ros.org/wiki/xacro" name="diffbot">

  <xacro:macro name="inertial_sphere" params="mass radius *origin">
    <inertial>
      <xacro:insert_block name="origin"/>
      <mass value="${mass}" />
      <inertia ixx="${(2/5) * mass * (radius*radius)}" ixy="0.0" ixz="0.0"
               iyy="${(2/5) * mass * (radius*radius)}" iyz="0.0"
               izz="${(2/5) * mass * (radius*radius)}" />
    </inertial>
  </xacro:macro>

  <xacro:macro name="inertial_box" params="mass x y z *origin">
    <inertial>
      <xacro:insert_block name="origin"/>
      <mass value="${mass}" />
      <inertia ixx="${(1/12) * mass * (y*y + z*z)}" ixy="0.0" ixz="0.0"
               iyy="${(1/12) * mass * (x*x + z*z)}" iyz="0.0"
               izz="${(1/12) * mass * (x*x + y*y)}" />
    </inertial>
  </xacro:macro>

  <xacro:macro name="inertial_cylinder" params="mass length radius *origin">
    <inertial>
      <xacro:insert_block name="origin"/>
      <mass value="${mass}" />
      <inertia ixx="${(1/12) * mass * (3*radius*radius + length*length)}" ixy="0.0" ixz="0.0"
               iyy="${(1/12) * mass * (3*radius*radius + length*length)}" iyz="0.0"
               izz="${(1/2) * mass * (radius*radius)}" />
    </inertial>
  </xacro:macro>

  <xacro:property name="chassis_length" value="0.2"/>
  <xacro:property name="chassis_width"  value="0.2"/>
  <xacro:property name="chassis_height" value="0.11"/>

  <xacro:property name="wheel_radius"    value="0.021"/>  
  <xacro:property name="wheel_thickness" value="0.02"/>   
  <xacro:property name="wheel_mass"      value="0.05"/>
  <xacro:property name="wheel_separation" value="0.22"/>
  <xacro:property name="wheel_offset_y"   value="${wheel_separation/2}"/> 
  <xacro:property name="front_wheel_x"    value="0.07"/>
  <xacro:property name="back_wheel_x"     value="-0.07"/>
  <xacro:property name="wheel_center_z"   value="${-chassis_height/2 - wheel_radius}"/> 

  <material name="white">
    <color rgba="1 1 1 1" />
  </material>
  <material name="orange">
    <color rgba="1 0.3 0.1 1"/>
  </material>
  <material name="blue">
    <color rgba="0.2 0.2 1 1"/>
  </material>
  <material name="black">
    <color rgba="0 0 0 1"/>
  </material>
  <material name="red">
    <color rgba="1 0 0 1"/>
  </material>

  <link name="base_link"/>

  <joint name="base_footprint_joint" type="fixed">
    <parent link="base_link"/>
    <child link="base_footprint"/>
    <origin xyz="0 0 -0.097" rpy="0 0 0"/>
  </joint>


  <link name="base_footprint"/>

  <joint name="chassis_joint" type="fixed">
    <parent link="base_link"/>
    <child link="chassis"/>
    <origin xyz="0 0 0"/>
  </joint>

  <link name="chassis">
    <visual>
      <origin xyz="0.07 0 -0.01" rpy="0 0 0"/>
      <geometry>
        <box size="0.06 0.2 0.09"/>
      </geometry>
      <material name="blue"/>
    </visual>
    <visual>
      <origin xyz="-0.03 0 0" rpy="0 0 0"/>
      <geometry>
        <box size="0.14 0.2 0.11"/>
      </geometry>
      <material name="blue"/>
    </visual>
    <collision>
      <origin xyz="0 0 0" rpy="0 0 0"/>
      <geometry>
        <box size="${chassis_length} ${chassis_width} ${chassis_height}"/>
      </geometry>
    </collision>
    <xacro:inertial_box mass="1.0" x="${chassis_length}" y="${chassis_width}" z="${chassis_height}">
      <origin xyz="0 0 0" rpy="0 0 0"/>
    </xacro:inertial_box>
  </link>

  <gazebo reference="chassis">
    <material>Gazebo/Blue</material>
  </gazebo>

  <joint name="front_left_wheel_joint" type="continuous">
    <parent link="base_link"/>
    <child link="front_left_wheel"/>
    <origin xyz="${front_wheel_x} ${wheel_offset_y} ${wheel_center_z}" rpy="-${pi/2} 0 0"/>
    <axis xyz="0 0 1"/>
  </joint>
  <link name="front_left_wheel">
    <visual>
      <origin xyz="0 0 0" rpy="0 0 0"/>
      <geometry>
        <cylinder radius="${wheel_radius}" length="${wheel_thickness}"/>
      </geometry>
      <material name="black"/>
    </visual>
    <collision>
      <origin xyz="0 0 0" rpy="0 0 0"/>
      <geometry>
        <cylinder radius="${wheel_radius}" length="${wheel_thickness}"/>
      </geometry>
    </collision>
    <xacro:inertial_cylinder mass="${wheel_mass}" length="${wheel_thickness}" radius="${wheel_radius}">
      <origin xyz="0 0 0" rpy="0 0 0"/>
    </xacro:inertial_cylinder>
  </link>
  <gazebo reference="front_left_wheel">
    <material>Gazebo/Black</material>
  </gazebo>

  <joint name="front_right_wheel_joint" type="continuous">
    <parent link="base_link"/>
    <child link="front_right_wheel"/>
    <origin xyz="${front_wheel_x} ${-wheel_offset_y} ${wheel_center_z}" rpy="${pi/2} 0 0"/>
    <axis xyz="0 0 -1"/>
  </joint>
  <link name="front_right_wheel">
    <visual>
      <origin xyz="0 0 0" rpy="0 0 0"/>
      <geometry>
        <cylinder radius="${wheel_radius}" length="${wheel_thickness}"/>
      </geometry>
      <material name="black"/>
    </visual>
    <collision>
      <origin xyz="0 0 0" rpy="0 0 0"/>
      <geometry>
        <cylinder radius="${wheel_radius}" length="${wheel_thickness}"/>
      </geometry>
    </collision>
    <xacro:inertial_cylinder mass="${wheel_mass}" length="${wheel_thickness}" radius="${wheel_radius}">
      <origin xyz="0 0 0" rpy="0 0 0"/>
    </xacro:inertial_cylinder>
  </link>
  <gazebo reference="front_right_wheel">
    <material>Gazebo/Black</material>
  </gazebo>

  <joint name="back_left_wheel_joint" type="continuous">
    <parent link="base_link"/>
    <child link="back_left_wheel"/>
    <origin xyz="${back_wheel_x} ${wheel_offset_y} ${wheel_center_z}" rpy="-${pi/2} 0 0"/>
    <axis xyz="0 0 1"/>
  </joint>
  <link name="back_left_wheel">
    <visual>
      <origin xyz="0 0 0" rpy="0 0 0"/>
      <geometry>
        <cylinder radius="${wheel_radius}" length="${wheel_thickness}"/>
      </geometry>
      <material name="black"/>
    </visual>
    <collision>
      <origin xyz="0 0 0" rpy="0 0 0"/>
      <geometry>
        <cylinder radius="${wheel_radius}" length="${wheel_thickness}"/>
      </geometry>
    </collision>
    <xacro:inertial_cylinder mass="${wheel_mass}" length="${wheel_thickness}" radius="${wheel_radius}">
      <origin xyz="0 0 0" rpy="0 0 0"/>
    </xacro:inertial_cylinder>
  </link>
  <gazebo reference="back_left_wheel">
    <material>Gazebo/Black</material>
  </gazebo>

  <joint name="back_right_wheel_joint" type="continuous">
    <parent link="base_link"/>
    <child link="back_right_wheel"/>
    <origin xyz="${back_wheel_x} ${-wheel_offset_y} ${wheel_center_z}" rpy="${pi/2} 0 0"/>
    <axis xyz="0 0 -1"/>
  </joint>
  <link name="back_right_wheel">
    <visual>
      <origin xyz="0 0 0" rpy="0 0 0"/>
      <geometry>
        <cylinder radius="${wheel_radius}" length="${wheel_thickness}"/>
      </geometry>
      <material name="black"/>
    </visual>
    <collision>
      <origin xyz="0 0 0" rpy="0 0 0"/>
      <geometry>
        <cylinder radius="${wheel_radius}" length="${wheel_thickness}"/>
      </geometry>
    </collision>
    <xacro:inertial_cylinder mass="${wheel_mass}" length="${wheel_thickness}" radius="${wheel_radius}">
      <origin xyz="0 0 0" rpy="0 0 0"/>
    </xacro:inertial_cylinder>
  </link>
  <gazebo reference="back_right_wheel">
    <material>Gazebo/Black</material>
  </gazebo>

  <joint name="laser_joint" type="fixed">
    <parent link="chassis"/>
    <child link="laser_frame"/>
    <origin xyz="-0.03 0 0.075" rpy="0 0 0"/>
  </joint>
  <link name="laser_frame">
    <visual>
      <origin xyz="0 0 0" rpy="0 0 0"/>
      <geometry>
        <cylinder radius="0.035" length="0.04"/>
      </geometry>
      <material name="orange"/>
    </visual>
    <visual>
      <origin xyz="0 0 -0.05" rpy="0 0 0"/>
      <geometry>
        <cylinder radius="0.01" length="0.1"/>
      </geometry>
      <material name="orange"/>
    </visual>
    <collision>
      <origin xyz="0 0 0" rpy="0 0 0"/>
      <geometry>
        <cylinder radius="0.035" length="0.04"/>
      </geometry>
    </collision>
    <xacro:inertial_cylinder mass="0.1" length="0.04" radius="0.035">
      <origin xyz="0 0 0" rpy="0 0 0"/>
    </xacro:inertial_cylinder>
  </link>

  <gazebo reference="laser_frame">
    <material>Gazebo/Orange</material>
    <sensor name="laser" type="ray">
      <pose>0 0 0 0 0 0</pose>
      <visualize>false</visualize>
      <update_rate>10</update_rate>
      <ray>
        <scan>
          <horizontal>
            <samples>360</samples>
            <min_angle>-3.14</min_angle>
            <max_angle>3.14</max_angle>
          </horizontal>
        </scan>
        <range>
          <min>0.3</min>
          <max>12</max>
        </range>
      </ray>
      <plugin name="laser_controller" filename="libgazebo_ros_ray_sensor.so">
        <ros>
          <argument>~/out:=scan</argument>
        </ros>
        <output_type>sensor_msgs/LaserScan</output_type>
        <frame_name>laser_frame</frame_name>
      </plugin>
    </sensor>
  </gazebo>

  <joint name="camera_joint" type="fixed">
      <parent link="chassis"/>
      <child link="camera_link"/>
      <origin xyz="0.11 0 0.03" rpy="0 0.45 0"/>
  </joint>
  
  <link name="camera_link">
      <visual>
          <origin xyz="-0.005 0 0" rpy="0 0 0"/>
          <geometry>
              <box size="0.007 0.02 0.02"/>
          </geometry>
          <material name="white"/>
      </visual>
      <collision>
          <origin xyz="0 0 0" rpy="0 0 0"/>
          <geometry>
              <box size="0.02 0.02 0.005"/>
          </geometry>
      </collision>
  </link>

  <joint name="camera_optical_joint" type="fixed">
      <parent link="camera_link"/>
      <child link="camera_link_optical"/>
      <origin xyz="0 0 0" rpy="${-pi/2} 0 ${-pi/2}"/>
  </joint>

  <link name="camera_link_optical"></link>

  <gazebo reference="camera_link">
    <material>Gazebo/Black</material>

    <sensor name="camera" type="camera">
        <pose>0 0 0 0 0 0</pose>
        <visualize>true</visualize>
        <update_rate>30</update_rate>
        <camera>
            <horizontal_fov>1.089</horizontal_fov>
            <image>
                <format>R8G8B8</format>
                <width>640</width>
                <height>480</height>
            </image>
            <clip>
                <near>0.02</near>
                <far>5.0</far>
            </clip>
        </camera>
        <plugin name="camera_controller" filename="libgazebo_ros_camera.so">
            <frame_name>camera_link_optical</frame_name>
        </plugin>
    </sensor>
  </gazebo>

  <joint name="spray_joint" type="fixed">
    <parent link="chassis"/>
    <child link="spray_link" />
    <origin xyz="0.1 -0.04 0.03" rpy="0 0 0"/>
  </joint>

  <link name="spray_link">
    <visual>
      <origin xyz="0 0 0" rpy="0 0 0"/>
      <geometry>
        <box size="0.005 0.005 0.005"/>
      </geometry>
      <material name="red">
        <color rgba="1 0 0 1"/>
      </material>
    </visual>
  </link>

  <ros2_control name="GazeboSystem" type="system">
    <hardware>
      <plugin>gazebo_ros2_control/GazeboSystem</plugin>
    </hardware>
    <joint name="front_left_wheel_joint">
      <command_interface name="velocity">
        <param name="min">-1</param>
        <param name="max">1</param>
      </command_interface>
      <state_interface name="velocity"/>
      <state_interface name="position"/>
    </joint>
    <joint name="back_left_wheel_joint">
      <command_interface name="velocity">
        <param name="min">-1</param>
        <param name="max">1</param>
      </command_interface>
      <state_interface name="velocity"/>
      <state_interface name="position"/>
    </joint>
    <joint name="front_right_wheel_joint">
      <command_interface name="velocity">
        <param name="min">-1</param>
        <param name="max">1</param>
      </command_interface>
      <state_interface name="velocity"/>
      <state_interface name="position"/>
    </joint>
    <joint name="back_right_wheel_joint">
      <command_interface name="velocity">
        <param name="min">-1</param>
        <param name="max">1</param>
      </command_interface>
      <state_interface name="velocity"/>
      <state_interface name="position"/>
    </joint>
  </ros2_control>

  <gazebo>
    <plugin filename="libgazebo_ros_diff_drive.so" name="differential_drive_controller">
      <update_rate>500</update_rate>
      <num_wheel_pairs>2</num_wheel_pairs>
      <left_joint>front_left_wheel_joint</left_joint>
      <right_joint>front_right_wheel_joint</right_joint>
      <left_joint>back_left_wheel_joint</left_joint>
      <right_joint>back_right_wheel_joint</right_joint>
      <wheel_separation>0.22</wheel_separation>
      <wheel_separation>0.22</wheel_separation>
      <wheel_diameter>0.021</wheel_diameter>
      <wheel_diameter>0.021</wheel_diameter>
      <max_wheel_torque>20</max_wheel_torque>
      <max_wheel_acceleration>1.0</max_wheel_acceleration>
      <publish_odom>true</publish_odom>
      <publish_odom_tf>true</publish_odom_tf>
      <publish_wheel_tf>true</publish_wheel_tf>
      <use_stamped_vel>false</use_stamped_vel>
      <odometry_frame>odom</odometry_frame>
      <robot_base_frame>base_link</robot_base_frame>
    </plugin>
  </gazebo>

</robot>
